<?xml version="1.0" ?>
<sdf version="1.8">
  <world name="warehouse_world">
    <physics name="1ms" type="ignore">
      <max_step_size>0.001</max_step_size>
      <real_time_factor>1.0</real_time_factor>
    </physics>
    <plugin filename="gz-sim-physics-system"
        name="gz::sim::systems::Physics">
    </plugin>
    <plugin filename="gz-sim-user-commands-system"
        name="gz::sim::systems::UserCommands">
    </plugin>
    <plugin filename="gz-sim-scene-broadcaster-system"
        name="gz::sim::systems::SceneBroadcaster">
    </plugin>

    <scene>
      <ambient>0.4 0.4 0.4 1</ambient>
      <background>0.7 0.7 0.7 1</background>
      <shadows>true</shadows>
    </scene>

    <light type="directional" name="sun">
      <cast_shadows>true</cast_shadows>
      <pose>0 0 10 0 0 0</pose>
      <diffuse>0.8 0.8 0.8 1</diffuse>
      <specular>0.2 0.2 0.2 1</specular>
      <attenuation>
        <range>1000</range>
        <constant>0.9</constant>
        <linear>0.01</linear>
        <quadratic>0.001</quadratic>
      </attenuation>
      <direction>-0.5 0.1 -0.9</direction>
    </light>

    <!-- Ground Plane -->
    <model name="ground_plane">
      <static>true</static>
      <link name="link">
        <collision name="collision">
          <geometry>
            <plane>
              <normal>0 0 1</normal>
              <size>20 20</size>
            </plane>
          </geometry>
        </collision>
        <visual name="visual">
          <geometry>
            <plane>
              <normal>0 0 1</normal>
              <size>20 20</size>
            </plane>
          </geometry>
          <material>
            <ambient>0.8 0.8 0.8 1</ambient>
            <diffuse>0.8 0.8 0.8 1</diffuse>
            <specular>0.8 0.8 0.8 1</specular>
          </material>
        </visual>
      </link>
    </model>

    <!-- Warehouse Shelves from Gazebo Fuel -->
    <include>
      <uri>https://fuel.gazebosim.org/1.0/MovAi/models/shelf</uri>
      <name>warehouse_shelf1</name>
      <pose>3 2 0 0 0 0</pose>
    </include>

    <include>
      <uri>https://fuel.gazebosim.org/1.0/MovAi/models/shelf</uri>
      <name>warehouse_shelf2</name>
      <pose>3 5 0 0 0 0</pose>
    </include>

    <include>
      <uri>https://fuel.gazebosim.org/1.0/MovAi/models/shelf</uri>
      <name>warehouse_shelf3</name>
      <pose>-3 2 0 0 0 0</pose>
    </include>

    <include>
      <uri>https://fuel.gazebosim.org/1.0/MovAi/models/shelf</uri>
      <name>warehouse_shelf4</name>
      <pose>-3 5 0 0 0 0</pose>
    </include>

    <!-- Warehouse Pallets from Gazebo Fuel -->
    <include>
      <uri>https://fuel.gazebosim.org/1.0/MovAi/models/pallet</uri>
      <name>pallet1</name>
      <pose>1 1 0 0 0 0</pose>
    </include>

    <include>
      <uri>https://fuel.gazebosim.org/1.0/OpenRobotics/models/Cardboard Box</uri>
      <name>box1</name>
      <pose>1 1 0.5 0 0 0</pose>
    </include>

    <include>
      <uri>https://fuel.gazebosim.org/1.0/MovAi/models/pallet</uri>
      <name>pallet2</name>
      <pose>-1 1 0 0 0 0</pose>
    </include>

    <include>
      <uri>https://fuel.gazebosim.org/1.0/OpenRobotics/models/Cardboard Box</uri>
      <name>box2</name>
      <pose>-1 1 0.5 0 0 0</pose>
    </include>

    <!-- Warehouse Equipment from Gazebo Fuel -->
    <include>
      <uri>https://fuel.gazebosim.org/1.0/OpenRobotics/models/Mecanum lift</uri>
      <name>forklift1</name>
      <pose>-4 -2 0 0 0 1.57</pose>
    </include>

    <!-- Sensor Box with Dummy Sensor -->
    <model name="sensor_box">
      <pose>0 0 0.5 0 0 0</pose>
      <link name="link">
        <collision name="collision">
          <geometry>
            <box>
              <size>0.5 0.5 0.5</size>
            </box>
          </geometry>
        </collision>
        <visual name="visual">
          <geometry>
            <box>
              <size>0.5 0.5 0.5</size>
            </box>
          </geometry>
          <material>
            <ambient>0 0.5 0.5 1</ambient>
            <diffuse>0 0.5 0.5 1</diffuse>
          </material>
        </visual>
      </link>
      <!-- This is where we add our dummy sensor plugin -->
      <plugin
        filename="libdummy_sensor.so"
        name="my_rfid_demo::DummySensor">
        <topic>/dummy_sensor</topic>
      </plugin>
    </model>

    <!-- Warehouse Robot Model (Direct inclusion instead of external reference) -->
    <model name="warehouse_robot">
      <pose>0 -2 0.1 0 0 0</pose>
      <!-- Base Link -->
      <link name="base_link">
        <visual name="visual">
          <geometry>
            <box>
              <size>0.5 0.5 0.2</size>
            </box>
          </geometry>
          <material>
            <ambient>0 0 0.8 1</ambient>
            <diffuse>0 0 0.8 1</diffuse>
            <specular>0 0 0.8 1</specular>
          </material>
        </visual>
        <collision name="collision">
          <geometry>
            <box>
              <size>0.5 0.5 0.2</size>
            </box>
          </geometry>
        </collision>
        <inertial>
          <mass>5.0</mass>
          <inertia>
            <ixx>0.1</ixx>
            <ixy>0</ixy>
            <ixz>0</ixz>
            <iyy>0.1</iyy>
            <iyz>0</iyz>
            <izz>0.1</izz>
          </inertia>
        </inertial>
      </link>

      <!-- Wheels -->
      <!-- Front Left Wheel -->
      <link name="front_left_wheel">
        <pose>0.2 0.2 -0.1 1.5708 0 0</pose>
        <visual name="visual">
          <geometry>
            <cylinder>
              <radius>0.1</radius>
              <length>0.05</length>
            </cylinder>
          </geometry>
          <material>
            <ambient>0.1 0.1 0.1 1</ambient>
            <diffuse>0.1 0.1 0.1 1</diffuse>
            <specular>0.1 0.1 0.1 1</specular>
          </material>
        </visual>
        <collision name="collision">
          <geometry>
            <cylinder>
              <radius>0.1</radius>
              <length>0.05</length>
            </cylinder>
          </geometry>
        </collision>
        <inertial>
          <mass>1.0</mass>
          <inertia>
            <ixx>0.01</ixx>
            <ixy>0</ixy>
            <ixz>0</ixz>
            <iyy>0.01</iyy>
            <iyz>0</iyz>
            <izz>0.01</izz>
          </inertia>
        </inertial>
      </link>

      <joint name="front_left_wheel_joint" type="revolute">
        <parent>base_link</parent>
        <child>front_left_wheel</child>
        <axis>
          <xyz>0 0 1</xyz>
          <limit>
            <lower>-1.79769e+308</lower>
            <upper>1.79769e+308</upper>
          </limit>
        </axis>
      </joint>

      <!-- Front Right Wheel -->
      <link name="front_right_wheel">
        <pose>0.2 -0.2 -0.1 1.5708 0 0</pose>
        <visual name="visual">
          <geometry>
            <cylinder>
              <radius>0.1</radius>
              <length>0.05</length>
            </cylinder>
          </geometry>
          <material>
            <ambient>0.1 0.1 0.1 1</ambient>
            <diffuse>0.1 0.1 0.1 1</diffuse>
            <specular>0.1 0.1 0.1 1</specular>
          </material>
        </visual>
        <collision name="collision">
          <geometry>
            <cylinder>
              <radius>0.1</radius>
              <length>0.05</length>
            </cylinder>
          </geometry>
        </collision>
        <inertial>
          <mass>1.0</mass>
          <inertia>
            <ixx>0.01</ixx>
            <ixy>0</ixy>
            <ixz>0</ixz>
            <iyy>0.01</iyy>
            <iyz>0</iyz>
            <izz>0.01</izz>
          </inertia>
        </inertial>
      </link>

      <joint name="front_right_wheel_joint" type="revolute">
        <parent>base_link</parent>
        <child>front_right_wheel</child>
        <axis>
          <xyz>0 0 1</xyz>
          <limit>
            <lower>-1.79769e+308</lower>
            <upper>1.79769e+308</upper>
          </limit>
        </axis>
      </joint>

      <!-- Rear Left Wheel -->
      <link name="rear_left_wheel">
        <pose>-0.2 0.2 -0.1 1.5708 0 0</pose>
        <visual name="visual">
          <geometry>
            <cylinder>
              <radius>0.1</radius>
              <length>0.05</length>
            </cylinder>
          </geometry>
          <material>
            <ambient>0.1 0.1 0.1 1</ambient>
            <diffuse>0.1 0.1 0.1 1</diffuse>
            <specular>0.1 0.1 0.1 1</specular>
          </material>
        </visual>
        <collision name="collision">
          <geometry>
            <cylinder>
              <radius>0.1</radius>
              <length>0.05</length>
            </cylinder>
          </geometry>
        </collision>
        <inertial>
          <mass>1.0</mass>
          <inertia>
            <ixx>0.01</ixx>
            <ixy>0</ixy>
            <ixz>0</ixz>
            <iyy>0.01</iyy>
            <iyz>0</iyz>
            <izz>0.01</izz>
          </inertia>
        </inertial>
      </link>

      <joint name="rear_left_wheel_joint" type="revolute">
        <parent>base_link</parent>
        <child>rear_left_wheel</child>
        <axis>
          <xyz>0 0 1</xyz>
          <limit>
            <lower>-1.79769e+308</lower>
            <upper>1.79769e+308</upper>
          </limit>
        </axis>
      </joint>

      <!-- Rear Right Wheel -->
      <link name="rear_right_wheel">
        <pose>-0.2 -0.2 -0.1 1.5708 0 0</pose>
        <visual name="visual">
          <geometry>
            <cylinder>
              <radius>0.1</radius>
              <length>0.05</length>
            </cylinder>
          </geometry>
          <material>
            <ambient>0.1 0.1 0.1 1</ambient>
            <diffuse>0.1 0.1 0.1 1</diffuse>
            <specular>0.1 0.1 0.1 1</specular>
          </material>
        </visual>
        <collision name="collision">
          <geometry>
            <cylinder>
              <radius>0.1</radius>
              <length>0.05</length>
            </cylinder>
          </geometry>
        </collision>
        <inertial>
          <mass>1.0</mass>
          <inertia>
            <ixx>0.01</ixx>
            <ixy>0</ixy>
            <ixz>0</ixz>
            <iyy>0.01</iyy>
            <iyz>0</iyz>
            <izz>0.01</izz>
          </inertia>
        </inertial>
      </link>

      <joint name="rear_right_wheel_joint" type="revolute">
        <parent>base_link</parent>
        <child>rear_right_wheel</child>
        <axis>
          <xyz>0 0 1</xyz>
          <limit>
            <lower>-1.79769e+308</lower>
            <upper>1.79769e+308</upper>
          </limit>
        </axis>
      </joint>

      <!-- RFID Sensor -->
      <link name="rfid_sensor">
        <pose>0.2 0 0.15 0 0 0</pose>
        <visual name="visual">
          <geometry>
            <box>
              <size>0.1 0.1 0.05</size>
            </box>
          </geometry>
          <material>
            <ambient>0.8 0 0 1</ambient>
            <diffuse>0.8 0 0 1</diffuse>
            <specular>0.8 0 0 1</specular>
          </material>
        </visual>
        <collision name="collision">
          <geometry>
            <box>
              <size>0.1 0.1 0.05</size>
            </box>
          </geometry>
        </collision>
        <inertial>
          <mass>0.1</mass>
          <inertia>
            <ixx>0.001</ixx>
            <ixy>0</ixy>
            <ixz>0</ixz>
            <iyy>0.001</iyy>
            <iyz>0</iyz>
            <izz>0.001</izz>
          </inertia>
        </inertial>
        <sensor name="rfid_sensor" type="custom">
          <plugin filename="libdummy_sensor.so" name="my_rfid_demo::DummySensor">
            <topic>/dummy_sensor</topic>
          </plugin>
        </sensor>
      </link>

      <joint name="rfid_sensor_joint" type="fixed">
        <parent>base_link</parent>
        <child>rfid_sensor</child>
      </joint>

      <!-- Differential drive plugin -->
      <plugin filename="gz-sim-diff-drive-system" name="gz::sim::systems::DiffDrive">
        <left_joint>front_left_wheel_joint</left_joint>
        <left_joint>rear_left_wheel_joint</left_joint>
        <right_joint>front_right_wheel_joint</right_joint>
        <right_joint>rear_right_wheel_joint</right_joint>
        <wheel_separation>0.4</wheel_separation>
        <wheel_radius>0.1</wheel_radius>
        <odom_publish_frequency>50</odom_publish_frequency>
        <topic>cmd_vel</topic>
      </plugin>
    </model>
  </world>
</sdf>