<?xml version="1.0"?>
<robot xmlns:xacro="http://www.ros.org/wiki/xacro" name="warehouse_robot">

  <!-- Define constants -->
  <xacro:property name="PI" value="3.1415926535897931"/>

  <!-- Base Link -->
  <link name="base_link">
    <visual>
      <geometry>
        <box size="0.5 0.5 0.2"/>
      </geometry>
      <material name="blue">
        <color rgba="0 0 0.8 1"/>
      </material>
    </visual>
    <collision>
      <geometry>
        <box size="0.5 0.5 0.2"/>
      </geometry>
    </collision>
    <inertial>
      <mass value="5.0"/>
      <inertia ixx="0.1" ixy="0" ixz="0" iyy="0.1" iyz="0" izz="0.1"/>
    </inertial>
  </link>

  <!-- Wheels -->
  <xacro:macro name="wheel" params="name x y">
    <link name="${name}_wheel">
      <visual>
        <geometry>
          <cylinder radius="0.1" length="0.05"/>
        </geometry>
        <material name="black">
          <color rgba="0.1 0.1 0.1 1"/>
        </material>
      </visual>
      <collision>
        <geometry>
          <cylinder radius="0.1" length="0.05"/>
        </geometry>
      </collision>
      <inertial>
        <mass value="1.0"/>
        <inertia ixx="0.01" ixy="0" ixz="0" iyy="0.01" iyz="0" izz="0.01"/>
      </inertial>
    </link>

    <joint name="${name}_wheel_joint" type="continuous">
      <parent link="base_link"/>
      <child link="${name}_wheel"/>
      <origin xyz="${x} ${y} -0.1" rpy="${PI/2} 0 0"/>
      <axis xyz="0 0 1"/>
    </joint>
  </xacro:macro>

  <xacro:wheel name="front_left" x="0.2" y="0.2"/>
  <xacro:wheel name="front_right" x="0.2" y="-0.2"/>
  <xacro:wheel name="rear_left" x="-0.2" y="0.2"/>
  <xacro:wheel name="rear_right" x="-0.2" y="-0.2"/>

  <!-- RFID Sensor -->
  <link name="rfid_sensor">
    <visual>
      <geometry>
        <box size="0.1 0.1 0.05"/>
      </geometry>
      <material name="red">
        <color rgba="0.8 0 0 1"/>
      </material>
    </visual>
    <collision>
      <geometry>
        <box size="0.1 0.1 0.05"/>
      </geometry>
    </collision>
    <inertial>
      <mass value="0.1"/>
      <inertia ixx="0.001" ixy="0" ixz="0" iyy="0.001" iyz="0" izz="0.001"/>
    </inertial>
  </link>

  <joint name="rfid_sensor_joint" type="fixed">
    <parent link="base_link"/>
    <child link="rfid_sensor"/>
    <origin xyz="0.2 0 0.15" rpy="0 0 0"/>
  </joint>

  <!-- Gazebo-specific elements -->
  <gazebo>
    <!-- Differential drive plugin -->
    <plugin filename="gz-sim-diff-drive-system" name="gz::sim::systems::DiffDrive">
      <left_joint>front_left_wheel_joint</left_joint>
      <left_joint>rear_left_wheel_joint</left_joint>
      <right_joint>front_right_wheel_joint</right_joint>
      <right_joint>rear_right_wheel_joint</right_joint>
      <wheel_separation>0.4</wheel_separation>
      <wheel_radius>0.1</wheel_radius>
      <odom_publish_frequency>50</odom_publish_frequency>
      <topic>cmd_vel</topic>
    </plugin>
  </gazebo>

  <!-- Add the dummy sensor plugin to the RFID sensor link -->
  <gazebo reference="rfid_sensor">
    <sensor name="rfid_sensor" type="custom">
      <plugin filename="libdummy_sensor.so" name="my_rfid_demo::DummySensor">
        <topic>/dummy_sensor</topic>
      </plugin>
    </sensor>
  </gazebo>
</robot>